Workbook

Sheet Allocation
A3: Sum of Confirmed Quantity (CS) | B3: Column Labels
A4: Row Labels | B4: 2910 | C4: 2920 | D4: 2925 | E4: 2930 | F4: (blank) | G4: Grand Total | H4: Unique Key
A5: 10001127 | B5: 0 | G5: 0 | H5: =A5 & "_" & 2910 -> 10001127_2910
A6: 10003061 | E6: 0 | G6: 0 | H6: =A6 & "_" & 2910 -> 10003061_2910
A7: 10007757 | B7: 0 | G7: 0 | H7: =A7 & "_" & 2910 -> 10007757_2910
A8: 10007843 | B8: 0 | C8: 8 | G8: 8 | H8: =A8 & "_" & 2910 -> 10007843_2910
A9: 10007849 | C9: 1 | G9: 1 | H9: =A9 & "_" & 2910 -> 10007849_2910
A10: 10007851 | C10: 74 | G10: 74 | H10: =A10 & "_" & 2910 -> 10007851_2910
A11: 10010749 | E11: 0 | G11: 0 | H11: =A11 & "_" & 2910 -> 10010749_2910
A12: 10010755 | B12: 0 | E12: 0 | G12: 0 | H12: =A12 & "_" & 2910 -> 10010755_2910
A13: 10011275 | E13: 0 | G13: 0 | H13: =A13 & "_" & 2910 -> 10011275_2910
A14: 10013039 | C14: 0 | E14: 2 | G14: 2 | H14: =A14 & "_" & 2910 -> 10013039_2910
A15: 10013105 | C15: 0 | E15: 0 | G15: 0 | H15: =A15 & "_" & 2910 -> 10013105_2910
A16: 10013128 | B16: 0 | G16: 0 | H16: =A16 & "_" & 2910 -> 10013128_2910
A17: 10013144 | B17: 0 | E17: 0 | G17: 0 | H17: =A17 & "_" & 2910 -> 10013144_2910
A18: 10016044 | B18: 0 | G18: 0 | H18: =A18 & "_" & 2910 -> 10016044_2910
A19: 10016081 | B19: 0 | E19: 0 | G19: 0 | H19: =A19 & "_" & 2910 -> 10016081_2910
A20: 10016204 | B20: 0 | C20: 0 | G20: 0 | H20: =A20 & "_" & 2910 -> 10016204_2910
A21: 10016401 | B21: 0 | G21: 0 | H21: =A21 & "_" & 2910 -> 10016401_2910
A22: 10016404 | E22: 0 | G22: 0 | H22: =A22 & "_" & 2910 -> 10016404_2910
A23: 10016408 | B23: 0 | G23: 0 | H23: =A23 & "_" & 2910 -> 10016408_2910
A24: 10017114 | E24: 0 | G24: 0 | H24: =A24 & "_" & 2910 -> 10017114_2910
A25: 10017604 | E25: 0 | G25: 0 | H25: =A25 & "_" & 2910 -> 10017604_2910
A26: 10017611 | B26: 0 | G26: 0 | H26: =A26 & "_" & 2910 -> 10017611_2910
A27: 10017617 | C27: 38 | G27: 38 | H27: =A27 & "_" & 2910 -> 10017617_2910
A28: 10018016 | B28: 0 | G28: 0 | H28: =A28 & "_" & 2910 -> 10018016_2910
A29: 10018053 | B29: 0 | G29: 0 | H29: =A29 & "_" & 2910 -> 10018053_2910
A30: 10018646 | B30: 0 | G30: 0 | H30: =A30 & "_" & 2910 -> 10018646_2910
A31: 10018656 | C31: 0 | G31: 0 | H31: =A31 & "_" & 2910 -> 10018656_2910
A32: 10018657 | B32: 0 | G32: 0 | H32: =A32 & "_" & 2910 -> 10018657_2910
A33: 10018659 | C33: 0 | E33: 0 | G33: 0 | H33: =A33 & "_" & 2910 -> 10018659_2910
A34: 10018661 | B34: 0 | G34: 0 | H34: =A34 & "_" & 2910 -> 10018661_2910
A35: 10018980 | B35: 0 | G35: 0 | H35: =A35 & "_" & 2910 -> 10018980_2910
A36: 10019107 | E36: 0 | G36: 0 | H36: =A36 & "_" & 2910 -> 10019107_2910
A37: 10019131 | B37: 0 | G37: 0 | H37: =A37 & "_" & 2910 -> 10019131_2910
A38: 10019641 | B38: 0 | C38: 0 | G38: 0 | H38: =A38 & "_" & 2910 -> 10019641_2910
A39: 10019648 | B39: 0 | G39: 0 | H39: =A39 & "_" & 2910 -> 10019648_2910
A40: 10019690 | B40: 0 | G40: 0 | H40: =A40 & "_" & 2910 -> 10019690_2910
A41: 10019703 | B41: 0 | E41: 0 | G41: 0 | H41: =A41 & "_" & 2910 -> 10019703_2910
A42: 10019704 | B42: 0 | C42: 0 | G42: 0 | H42: =A42 & "_" & 2910 -> 10019704_2910
...

Sheet Overstock
A1: Sales Order | B1: Sales Order Item | C1: Key Account # | D1: Sales Order Type | E1: Creation Date | F1: Order Status | G1: Rejection Status | H1: Sold To Party | I1: Ship To Party | J1: Material | K1: Material Description | L1: Order Quantity (CS) | M1: Confirmed Quantity (CS) | N1: Picked Quantity (CS) | O1: Invoice Quantity (CS) | P1: Invoice # | Q1: Outbound Delivery # | R1: Confirmed Quantity (KG) | S1: Invoice Item Amount | T1: Invoice Quantity (KG) | U1: Item Net Amount | V1: Item Net Amount (Confirmed) | W1: Order Quantity | X1: Order Quantity (KG) | Y1: Picked Quantity (KG) | Z1: Plant | AA1: Ship To Name | AB1: BBD / Shelf Life | AC1: Item Value | AD1: Requested Delivery Date | AE1: Ship to Arrive Date
A2: 3002794 | B2: 20 | C2: ONIND | D2: ZORA | E2: 45790 | F2: C | G2: A | H2: 10214530 | I2: 20214530 | J2: 10018980 | K2: DC CLOTTED CREAM 12X170G | L2: 2 | M2: 0 | N2: 0 | O2: 0 | R2: 0 | S2: 0 | T2: 0 | U2: 60 | V2: 0 | W2: 2 | X2: 0 | Y2: 0 | Z2: 2910 | AA2: NIAGARA HOME BAKERY | AC2: 95.6 | AD2: 45791
A3: 3008049 | B3: 20 | C3: ONIND | D3: ZORA | E3: 45814 | F3: C | G3: A | H3: 10117761 | I3: 20117761 | J3: 10019778 | K3: SNO AMBER MIST 6X200G | L3: 50 | M3: 0 | N3: 0 | O3: 0 | R3: 0 | S3: 0 | T3: 0 | U3: 1000 | V3: 0 | W3: 50 | X3: 0 | Y3: 0 | Z3: 2910 | AA3: MENDEL'S GLOBAL CHEESE (ONLY) | AC3: 917.5 | AD3: 45820
A4: 3008050 | B4: 20 | C4: ONIND | D4: ZORA | E4: 45814 | F4: C | G4: A | H4: 10117598 | I4: 20117598 | J4: 10019778 | K4: SNO AMBER MIST 6X200G | L4: 5 | M4: 0 | N4: 0 | O4: 0 | R4: 0 | S4: 0 | T4: 0 | U4: 100 | V4: 0 | W4: 5 | X4: 0 | Y4: 0 | Z4: 2910 | AA4: FOOD DEPOT INT INC (WHOLESALE) | AC4: 91.75 | AD4: 45820
A5: 3008307 | B5: 30 | C5: ONIND | D5: ZORA | E5: 45817 | F5: C | G5: A | H5: 10717283 | I5: 20717283 | J5: 10019778 | K5: SNO AMBER MIST 6X200G | L5: 3 | M5: 0 | N5: 0 | O5: 0 | R5: 0 | S5: 0 | T5: 0 | U5: 60 | V5: 0 | W5: 3 | X5: 0 | Y5: 0 | Z5: 2910 | AA5: LA BOTTEGA (CHEESE) | AC5: 55.05 | AD5: 45819
A6: 3009475 | B6: 220 | C6: BCIND | D6: ZORA | E6: 45821 | F6: C | G6: A | H6: 10066089 | I6: 20066089 | J6: 10018659 | K6: SOH PRETZELS MINI | L6: 1 | M6: 0 | N6: 0 | O6: 0 | R6: 0 | S6: 0 | T6: 0 | U6: 18.9 | V6: 0 | W6: 1 | X6: 0 | Y6: 0 | Z6: 2930 | AA6: SUNRISE MARKET CLEAROUT | AC6: 27.41 | AD6: 45824
A7: 3010042 | B7: 30 | C7: LIQID | D7: ZORA | E7: 45825 | F7: C | G7: A | H7: 10000912 | I7: 20000912 | J7: 10052114 | K7: STW 170G FIRM APPNZLR STYL | L7: 41 | M7: 0 | N7: 0 | O7: 0 | R7: 0 | S7: 0 | T7: 0 | U7: 41 | V7: 0 | W7: 41 | X7: 0 | Y7: 0 | Z7: 2920 | AA7: NUTRI-GLOBE-P/U FROM CALGARY W/H | AC7: 3019.65 | AD7: 45826
A8: 3010875 | B8: 20 | C8: FSIND | D8: ZORA | E8: 45828 | F8: C | G8: A | H8: 10074880 | I8: 20074880 | J8: 10019778 | K8: SNO AMBER MIST 6X200G | L8: 30 | M8: 0 | N8: 0 | O8: 0 | R8: 0 | S8: 0 | T8: 0 | U8: 510 | V8: 0 | W8: 30 | X8: 0 | Y8: 0 | Z8: 2910 | AA8: WORLDWIDE SPECIALTY FOODS LTD | AC8: 550.5 | AD8: 45833
A9: 3011082 | B9: 30 | C9: ATIND | D9: ZORA | E9: 45831 | F9: C | G9: A | H9: 10000813 | I9: 20000813 | J9: 10018053 | K9: IRELAND MATURE CHED BULK 2X2.5KG | L9: 8 | M9: 0 | N9: 0 | O9: 0 | R9: 0 | S9: 0 | T9: 0 | U9: 448.4 | V9: 0 | W9: 8 | X9: 40 | Y9: 0 | Z9: 2910 | AA9: DOLMA FOOD | AC9: 524.8 | AD9: 45835
A10: 3011635 | B10: 20 | C10: ATIND | D10: ZORA | E10: 45833 | G10: A | H10: 10120116 | I10: 20120116 | J10: 10019778 | K10: SNO AMBER MIST 6X200G | L10: 30 | M10: 0 | N10: 0 | O10: 0 | R10: 0 | S10: 0 | T10: 0 | U10: 510 | V10: 0 | W10: 30 | X10: 0 | Y10: 0 | Z10: 2910 | AA10: MULDER MEATS (1983) LTD | AC10: 550.5 | AD10: 45838
A11: 3011635 | B11: 70 | C11: ATIND | D11: ZORA | E11: 45833 | G11: A | H11: 10120116 | I11: 20120116 | J11: 10018053 | K11: IRELAND MATURE CHED BULK 2X2.5KG | L11: 10 | M11: 0 | N11: 0 | O11: 0 | R11: 0 | S11: 0 | T11: 0 | U11: 560.5 | V11: 0 | W11: 10 | X11: 50 | Y11: 0 | Z11: 2910 | AA11: MULDER MEATS (1983) LTD | AC11: 656 | AD11: 45838
A12: 3013228 | B12: 40 | C12: ONIND | D12: ZORA | E12: 45840 | F12: C | G12: A | H12: 10120219 | I12: 20120219 | J12: 10019778 | K12: SNO AMBER MIST 6X200G | L12: 2 | M12: 0 | N12: 0 | O12: 0 | R12: 0 | S12: 0 | T12: 0 | U12: 32 | V12: 0 | W12: 2 | X12: 0 | Y12: 0 | Z12: 2910 | AA12: THE MILL STREET CHEESE MARKET | AC12: 36.7 | AD12: 45842
A13: 3015332 | B13: 10 | C13: BCIND | D13: ZORA | E13: 45849 | F13: C | G13: A | H13: 10049999 | I13: 20049999 | J13: 10061010 | K13: BEL BOUR 150G GARLIC & HERB | L13: 51 | M13: 0 | N13: 0 | O13: 0 | R13: 0 | S13: 0 | T13: 0 | U13: 459 | V13: 0 | W13: 51 | X13: 0 | Y13: 0 | Z13: 2930 | AA13: OLD COUNTRY MKT ALBERNI DELI | AC13: 2557.65 | AD13: 45850
A14: 3015332 | B14: 100 | C14: BCIND | D14: ZORA | E14: 45849 | F14: C | G14: A | H14: 10049999 | I14: 20049999 | J14: 10016081 | K14: CLAWSON HUNTSMN 5 LAY BULK 2X2KG | L14: 4 | M14: 0 | N14: 0 | O14: 0 | R14: 0 | S14: 0 | T14: 0 | U14: 160 | V14: 0 | W14: 4 | X14: 16 | Y14: 0 | Z14: 2930 | AA14: OLD COUNTRY MKT ALBERNI DELI | AC14: 362.4 | AD14: 45850
A15: 3016217 | B15: 90 | C15: ONIND | D15: ZORA | E15: 45854 | F15: C | G15: A | H15: 10125105 | I15: 20125105 | J15: 10040122 | K15: BAL SNACKS CHOCO LATTE | L15: 30 | M15: 0 | N15: 0 | O15: 0 | R15: 0 | S15: 0 | T15: 0 | U15: 240 | V15: 0 | W15: 30 | X15: 0 | Y15: 0 | Z15: 2910 | AA15: ELLIOT LAKE MEATS AND DELI | AC15: 842.1 | AD15: 45859
A16: 3019222 | B16: 90 | C16: BCIND | D16: ZORA | E16: 45867 | F16: C | G16: A | H16: 10049999 | I16: 20049999 | J16: 10016081 | K16: CLAWSON HUNTSMN 5 LAY BULK 2X2KG | L16: 7 | M16: 0 | N16: 0 | O16: 0 | R16: 0 | S16: 0 | T16: 0 | U16: 336 | V16: 0 | W16: 7 | X16: 28 | Y16: 0 | Z16: 2930 | AA16: OLD COUNTRY MKT ALBERNI DELI | AC16: 634.2 | AD16: 45870
A17: 3019356 | B17: 100 | C17: LIQID | D17: ZORA | E17: 45868 | F17: C | G17: A | H17: 10150032 | I17: 20150032 | J17: 10019780 | K17: SNO BLACK BOMBER 1X2KG | L17: 9 | M17: 0 | N17: 0 | O17: 0 | R17: 0 | S17: 0 | T17: 0 | U17: 126 | V17: 0 | W17: 9 | X17: 18 | Y17: 0 | Z17: 2910 | AA17: COUNTRY TRADITIONS FROZEN FOODS | AC17: 512.82 | AD17: 45870
A18: 3019356 | B18: 140 | C18: LIQID | D18: ZORA | E18: 45868 | F18: C | G18: A | H18: 10150032 | I18: 20150032 | J18: 10050619 | K18: CB CRUNCHY PEANUT BUTTER | L18: 2 | M18: 0 | N18: 0 | O18: 0 | R18: 0 | S18: 0 | T18: 0 | U18: 12 | V18: 0 | W18: 2 | X18: 0 | Y18: 0 | Z18: 2910 | AA18: COUNTRY TRADITIONS FROZEN FOODS | AC18: 33.52 | AD18: 45870
A19: 3019752 | B19: 230 | C19: BCIND | D19: ZORA | E19: 45869 | F19: C | G19: A | H19: 10062506 | I19: 20062506 | J19: 10010749 | K19: CL GOODA CHEESE SPICED | L19: 3 | M19: 0 | N19: 0 | O19: 0 | R19: 0 | S19: 0 | T19: 0 | U19: 40.5 | V19: 0 | W19: 3 | X19: 13.5 | Y19: 0 | Z19: 2930 | AA19: LO-BOY MARKET CLEARANCE | AC19: 167.27 | AD19: 45874
A20: 3019752 | B20: 260 | C20: BCIND | D20: ZORA | E20: 45869 | F20: C | G20: A | H20: 10062506 | I20: 20062506 | J20: 10066217 | K20: KC SEA SALT 56G GF | L20: 18 | M20: 0 | N20: 0 | O20: 0 | R20: 0 | S20: 0 | T20: 0 | U20: 72 | V20: 0 | W20: 18 | X20: 0 | Y20: 0 | Z20: 2930 | AA20: LO-BOY MARKET CLEARANCE | AC20: 412.56 | AD20: 45874
A21: 3019989 | B21: 180 | C21: LIQID | D21: ZORA | E21: 45870 | F21: C | G21: A | H21: 10225936 | I21: 20225936 | J21: 10016044 | K21: CC CHED W HORSERADISH 12X150G | L21: 20 | M21: 0 | N21: 0 | O21: 0 | R21: 0 | S21: 0 | T21: 0 | U21: 160 | V21: 0 | W21: 20 | X21: 0 | Y21: 0 | Z21: 2910 | AA21: ALMOST PERFECT | AC21: 653.2 | AD21: 45876
A22: 3021494 | B22: 10 | C22: LIQID | D22: ZORA | E22: 45880 | F22: C | G22: A | H22: 10000913 | I22: 20000913 | J22: 10063102 | K22: CAPE CHIPS SALT LS FAT 220G | L22: 4 | M22: 0 | N22: 0 | O22: 0 | R22: 0 | S22: 0 | T22: 0 | U22: 12 | V22: 0 | W22: 4 | X22: 0 | Y22: 0 | Z22: 2930 | AA22: NUTRI-GLOBE-P/U FR SURREY BRANCH | AC22: 149.72 | AD22: 45883
A23: 3022985 | B23: 10 | C23: ONIND | D23: ZORA | E23: 45888 | F23: C | G23: A | H23: 10130665 | I23: 20130665 | J23: 10019780 | K23: SNO BLACK BOMBER 1X2KG | L23: 6 | M23: 0 | N23: 0 | O23: 0 | R23: 0 | S23: 0 | T23: 0 | U23: 228 | V23: 0 | W23: 6 | X23: 12 | Y23: 0 | Z23: 2910 | AA23: SCHEFFLERS MEAT (CHEESE) | AC23: 311.4 | AD23: 45889
... A79: 3056334 | B79: 50 | C79: ONIND | D79: ZORA | E79: 46062 | F79: C | G79: A | H79: 10159306 | I79: 20159306 | J79: 10061010 | K79: BEL BOUR 150G GARLIC & HERB | L79: 116 | M79: 0 | N79: 0 | O79: 0 | R79: 0 | S79: 0 | T79: 0 | U79: 2061.32 | V79: 0 | W79: 116 | X79: 0 | Y79: 0 | Z79: 2910 | AA79: ZARKY'S FINE FOODS | AC79: 5809.28 | AD79: 46064
A80: 3056403 | B80: 30 | C80: ONIND | D80: ZORA | E80: 46062 | G80: A | H80: 10117854 | I80: 20117854 | J80: 10016081 | K80: CLAWSON HUNTSMN 5 LAY BULK 2X2KG | L80: 28 | M80: 0 | N80: 0 | O80: 0 | R80: 0 | S80: 0 | T80: 0 | U80: 1237.6 | V80: 0 | W80: 28 | X80: 112 | Y80: 0 | Z80: 2910 | AA80: MENDEL'S GLOBAL CHEESE (ONLY) | AC80: 2736.16 | AD80: 46064
A81: 3056411 | B81: 70 | C81: ATIND | D81: ZORA | E81: 46062 | F81: C | G81: A | H81: 10780161 | I81: 20780161 | J81: 10061010 | K81: BEL BOUR 150G GARLIC & HERB | L81: 50 | M81: 0 | N81: 0 | O81: 0 | R81: 0 | S81: 0 | T81: 0 | U81: 888.5 | V81: 0 | W81: 50 | X81: 0 | Y81: 0 | Z81: 2910 | AA81: CANNING & CORNWALLIS VALUFOODS | AC81: 2504 | AD81: 46070
A82: 3056435 | B82: 20 | C82: LIQID | D82: ZORA | E82: 46062 | F82: C | G82: A | H82: 10123006 | I82: 21000245 | J82: 10061010 | K82: BEL BOUR 150G GARLIC & HERB | L82: 50 | M82: 0 | N82: 0 | O82: 0 | R82: 0 | S82: 0 | T82: 0 | U82: 888.5 | V82: 0 | W82: 50 | X82: 0 | Y82: 0 | Z82: 2910 | AA82: NUTRI-GLOBE MARKETING | AC82: 2504 | AD82: 46065
A83: 3056492 | B83: 30 | C83: ONIND | D83: ZORA | E83: 46063 | G83: A | H83: 10110520 | I83: 20110520 | J83: 10019703 | K83: OKA CHEESE SWIS SMKD 1X4.5KG | L83: 5 | M83: 0 | N83: 0 | O83: 0 | R83: 0 | S83: 0 | T83: 0 | U83: 167.18 | V83: 0 | W83: 5 | X83: 22.5 | Y83: 0 | Z83: 2910 | AA83: LADY YORK | AC83: 486.68 | AD83: 46065
A84: 3056492 | B84: 40 | C84: ONIND | D84: ZORA | E84: 46063 | G84: A | H84: 10110520 | I84: 20110520 | J84: 10016081 | K84: CLAWSON HUNTSMN 5 LAY BULK 2X2KG | L84: 28 | M84: 0 | N84: 0 | O84: 0 | R84: 0 | S84: 0 | T84: 0 | U84: 1237.6 | V84: 0 | W84: 28 | X84: 112 | Y84: 0 | Z84: 2910 | AA84: LADY YORK | AC84: 2736.16 | AD84: 46065
A85: 3056507 | B85: 20 | C85: ATIND | D85: ZORA | E85: 46063 | F85: C | G85: A | H85: 10125620 | I85: 20125620 | J85: 10016081 | K85: CLAWSON HUNTSMN 5 LAY BULK 2X2KG | L85: 2 | M85: 0 | N85: 0 | O85: 0 | R85: 0 | S85: 0 | T85: 0 | U85: 88.4 | V85: 0 | W85: 2 | X85: 8 | Y85: 0 | Z85: 2910 | AA85: MASSTOWN CREAMERY LTD | AC85: 195.44 | AD85: 46070
A86: 3056525 | B86: 170 | C86: ONIND | D86: ZORA | E86: 46063 | F86: C | G86: A | H86: 10125105 | I86: 20125105 | J86: 10061010 | K86: BEL BOUR 150G GARLIC & HERB | L86: 116 | M86: 0 | N86: 0 | O86: 0 | R86: 0 | S86: 0 | T86: 0 | U86: 2061.32 | V86: 0 | W86: 116 | X86: 0 | Y86: 0 | Z86: 2910 | AA86: ELLIOT LAKE MEATS AND DELI | AC86: 5809.28 | AD86: 46070
A87: 3056729 | B87: 100 | C87: BCIND | D87: ZORA | E87: 46063 | F87: C | G87: A | H87: 10001663 | I87: 20001663 | J87: 10066215 | K87: KC HONEY DIJON 56G GF | L87: 8 | M87: 0 | N87: 0 | O87: 0 | R87: 0 | S87: 0 | T87: 0 | U87: 53.28 | V87: 0 | W87: 8 | X87: 0 | Y87: 0 | Z87: 2930 | AA87: FALCON ESSENTIALS | AC87: 197.84 | AD87: 46066
A88: 3058318 | B88: 160 | C88: LIQID | D88: ZORA | E88: 46071 | F88: C | G88: A | H88: 10123006 | I88: 21000245 | J88: 10061008 | K88: BEL BOUR 150G CRACKD BLK PEP | L88: 28 | M88: 0 | N88: 0 | O88: 0 | R88: 0 | S88: 0 | T88: 0 | U88: 248.92 | V88: 0 | W88: 28 | X88: 0 | Y88: 0 | Z88: 2910 | AA88: NUTRI-GLOBE MARKETING | AC88: 704.76 | AD88: 46073
A89: 3058545 | B89: 40 | C89: ATIND | D89: ZORA | E89: 46072 | F89: C | G89: A | H89: 10125176 | I89: 20125176 | J89: 10019641 | K89: AGROSGN BRIE CHEVALR TC 650G | L89: 2 | M89: 0 | N89: 0 | O89: 0 | R89: 0 | S89: 0 | T89: 0 | U89: 35.41 | V89: 0 | W89: 2 | X89: 5.2 | Y89: 0 | Z89: 2910 | AA89: G&J GROCERY LTD | AC89: 142.58 | AD89: 46077
A90: 3058752 | B90: 200 | C90: BCIND | D90: ZORA | E90: 46073 | F90: C | G90: A | H90: 10062506 | I90: 20062506 | J90: 10033175 | K90: BC 540G OLD CHEDDAR CHEESE | L90: 8 | M90: 0 | N90: 0 | O90: 0 | R90: 0 | S90: 0 | T90: 0 | U90: 160 | V90: 0 | W90: 8 | X90: 0 | Y90: 0 | Z90: 2920 | AA90: LO-BOY MARKET CLEARANCE | AC90: 938.88 | AD90: 46077
A91: 3059050 | B91: 10 | C91: PRIND | D91: ZORA | E91: 46076 | F91: C | G91: A | H91: 13000090 | I91: 21000165 | J91: 10065013 | K91: G.H. POPCORN CARAMEL 227G | L91: 20 | M91: 0 | N91: 0 | O91: 0 | R91: 0 | S91: 0 | T91: 0 | U91: 259.6 | V91: 0 | W91: 20 | X91: 0 | Y91: 0 | Z91: 2920 | AA91: Liquidation Warehouse | AC91: 819 | AD91: 46079
A92: 3059246 | B92: 10 | C92: ATIND | D92: ZORA | E92: 46077 | F92: C | G92: A | H92: 13000158 | I92: 21000254 | J92: 10019703 | K92: OKA CHEESE SWIS SMKD 1X4.5KG | L92: 20 | M92: 0 | N92: 0 | O92: 0 | R92: 0 | S92: 0 | T92: 0 | U92: 668.7 | V92: 0 | W92: 20 | X92: 90 | Y92: 0 | Z92: 2910 | AA92: MULHOUSE FINE FOODS | AC92: 2009.7 | AD92: 46083
A93: 3059261 | B93: 10 | C93: ONIND | D93: ZORA | E93: 46077 | F93: C | G93: A | H93: 10125105 | I93: 20125105 | J93: 10019703 | K93: OKA CHEESE SWIS SMKD 1X4.5KG | L93: 20 | M93: 0 | N93: 0 | O93: 0 | R93: 0 | S93: 0 | T93: 0 | U93: 668.7 | V93: 0 | W93: 20 | X93: 90 | Y93: 0 | Z93: 2910 | AA93: ELLIOT LAKE MEATS AND DELI | AC93: 2009.7 | AD93: 46083
A94: 3059261 | B94: 130 | C94: ONIND | D94: ZORA | E94: 46077 | F94: C | G94: A | H94: 10125105 | I94: 20125105 | J94: 10067042 | K94: KC AIR FRIED TEXAS BBQ GF | L94: 2 | M94: 0 | N94: 0 | O94: 0 | R94: 0 | S94: 0 | T94: 0 | U94: 16 | V94: 0 | W94: 2 | X94: 0 | Y94: 0 | Z94: 2910 | AA94: ELLIOT LAKE MEATS AND DELI | AC94: 56.38 | AD94: 46083
A95: 3059261 | B95: 170 | C95: ONIND | D95: ZORA | E95: 46077 | F95: C | G95: A | H95: 10125105 | I95: 20125105 | J95: 10018646 | K95: SOH PRETZEL PIECE CHEDDAR | L95: 25 | M95: 0 | N95: 0 | O95: 0 | R95: 0 | S95: 0 | T95: 0 | U95: 200 | V95: 0 | W95: 25 | X95: 0 | Y95: 0 | Z95: 2910 | AA95: ELLIOT LAKE MEATS AND DELI | AC95: 666.25 | AD95: 46083
...

Sheet Price List
A1: BDM | B1: Brand Name | C1: Material | D1: Description | E1: Pack | F1: Size | G1: Pricing Date | H1: 1 - Store Door | I1: 2 - Wholesale | J1: Plant | K1: Sold by Wt
A2: NANCY QUISPE PT | B2: JARRITOS | C2: 10001116 | D2: JARRITOS TAMARIND SOFT DRINK | E2: 24 | F2: 370 ML | G2: 46238 | H2: 38.87 | I2: 34.66 | J2: 2910 | K2: 0
A3: NANCY QUISPE PT | B3: JARRITOS | C3: 10001117 | D3: JARRITOS MANDARIN SOFT DRINK | E3: 24 | F3: 370 ML | G3: 46238 | H3: 38.87 | I3: 34.66 | J3: 2910 | K3: 0
A4: NANCY QUISPE PT | B4: JARRITOS | C4: 10001118 | D4: JARRITOS COLA SOFT DRINK | E4: 24 | F4: 370 ML | G4: 46238 | H4: 38.87 | I4: 34.66 | J4: 2910 | K4: 0
A5: NANCY QUISPE PT | B5: JARRITOS | C5: 10001119 | D5: JARRITOS GUAVA SOFT DRINK | E5: 24 | F5: 370 ML | G5: 46238 | H5: 38.87 | I5: 34.66 | J5: 2910 | K5: 0
A6: NANCY QUISPE PT | B6: JARRITOS | C6: 10001120 | D6: JARRITOS LIME SOFT DRINK | E6: 24 | F6: 370 ML | G6: 46238 | H6: 38.87 | I6: 34.66 | J6: 2910 | K6: 0
A7: NANCY QUISPE PT | B7: JARRITOS | C7: 10001121 | D7: JARRITOS PINEAPPLE SOFT DRINK | E7: 24 | F7: 370 ML | G7: 46238 | H7: 38.87 | I7: 34.66 | J7: 2910 | K7: 0
A8: NANCY QUISPE PT | B8: JARRITOS | C8: 10001122 | D8: JARRITOS FRUIT PUNCH SOFT DRINK | E8: 24 | F8: 370 ML | G8: 46238 | H8: 38.87 | I8: 34.66 | J8: 2910 | K8: 0
A9: NANCY QUISPE PT | B9: JARRITOS | C9: 10001123 | D9: JARRITOS GRAPEFRUIT SOFT DRINK | E9: 24 | F9: 370 ML | G9: 46238 | H9: 38.87 | I9: 34.66 | J9: 2910 | K9: 0
A10: NANCY QUISPE PT | B10: JARRITOS | C10: 10001126 | D10: JARRITOS STRAWBERRY SOFT DRINK | E10: 24 | F10: 370 ML | G10: 46238 | H10: 38.87 | I10: 34.66 | J10: 2910 | K10: 0
A11: NANCY QUISPE PT | B11: JARRITOS | C11: 10001127 | D11: JARRITOS MANGO SOFT DRINK | E11: 24 | F11: 370 ML | G11: 46238 | H11: 38.87 | I11: 34.66 | J11: 2910 | K11: 0
A12: NANCY QUISPE PT | B12: SANGRIA SENORIAL | C12: 10001128 | D12: SANGRIA SENORIAL GRAPE CIDER SOFT DRINK | E12: 24 | F12: 330 ML | G12: 46238 | H12: 37.68 | I12: 33.6 | J12: 2910 | K12: 0
A13: NANCY QUISPE PT | B13: JARRITOS | C13: 10001134 | D13: JARRITOS WATERMELON SOFT DRINK | E13: 24 | F13: 370 ML | G13: 46238 | H13: 38.87 | I13: 34.66 | J13: 2910 | K13: 0
... A3297: TRACEY LAWRENCE | B3297: SNACK FACTORY | C3297: 50100024 | D3297: Snack Factory Rack Walmart | E3297: 1 | F3297: RACK | G3297: 46238 | H3297: 0 | I3297: 0 | J3297: 2910 | K3297: 0

Sheet Old report
A1: BDM | B1: Material Group Name | C1: Material | D1: Material Description | E1: Sold by KG | F1: Pack | G1: Size | H1: Plant | I1: Plant Name | J1: Batch | K1: Storage Location | L1: Shelf Life Expiration Date | M1: Unrestricted Stock | N1: Unique Key | O1: Allocation | P1: Available
A2: =_xlfn.XLOOKUP(C:C,'Price List'!C:C,'Price List'!A:A) -> JAMES TYSON | B2: VEGGIES MADE GREAT | C2: 10015389 | D2: VMG BRC&CHS BRKFST BKE POTAT | E2: =_xlfn.XLOOKUP(C:C,'Price List'!C:C,'Price List'!K:K) -> 0 | F2: =_xlfn.XLOOKUP(C:C,'Price List'!C:C,'Price List'!E:E) -> 8 | G2: =_xlfn.XLOOKUP(C:C,'Price List'!C:C,'Price List'!F:F) -> 340 GR | H2: 2925 | I2: Lineage Calgary CS | J2: 260516 | K2: 1100 | L2: 46158 | M2: 29 | N2: =C2 & "_" & 2910 -> 10015389_2910 | O2: =_xlfn.XLOOKUP(N2,Allocation!H:H,Allocation!C:C,0) -> 0 | P2: =M2-O2 -> 29
A3: =_xlfn.XLOOKUP(C:C,'Price List'!C:C,'Price List'!A:A) -> NISA DELEON | B3: CLIF BAR | C3: 10050613 | D3: CB WH CHOC MACAD NUT | E3: =_xlfn.XLOOKUP(C:C,'Price List'!C:C,'Price List'!K:K) -> 0 | F3: =_xlfn.XLOOKUP(C:C,'Price List'!C:C,'Price List'!E:E) -> 12 | G3: =_xlfn.XLOOKUP(C:C,'Price List'!C:C,'Price List'!F:F) -> 68 GR | H3: 2920 | I3: TOL Calgary | J3: IN15925012 | K3: 1100 | L3: 46161 | M3: 49 | N3: =C3 & "_" & 2910 -> 10050613_2910 | O3: =_xlfn.XLOOKUP(N3,Allocation!H:H,Allocation!C:C,0) -> 0 | P3: =M3-O3 -> 49
A4: =_xlfn.XLOOKUP(C:C,'Price List'!C:C,'Price List'!A:A) -> AMOL PRAKASH | B4: KINNIKINNICK | C4: 10015807 | D4: KKF FZN DONUT CHOC DIPPED | E4: =_xlfn.XLOOKUP(C:C,'Price List'!C:C,'Price List'!K:K) -> 0 | F4: =_xlfn.XLOOKUP(C:C,'Price List'!C:C,'Price List'!E:E) -> 8 | G4: =_xlfn.XLOOKUP(C:C,'Price List'!C:C,'Price List'!F:F) -> 320 GR | H4: 2925 | I4: Lineage Calgary CS | J4: 2026MA25 | K4: 1100 | L4: 46167 | M4: 6 | N4: =C4 & "_" & 2910 -> 10015807_2910 | O4: =_xlfn.XLOOKUP(N4,Allocation!H:H,Allocation!C:C,0) -> 0 | P4: =M4-O4 -> 6
A5: =_xlfn.XLOOKUP(C:C,'Price List'!C:C,'Price List'!A:A) -> WARREN PARK | B5: LAID BACK SNACKS | C5: 10020850 | D5: LBS HEARTY TAMARI 45G PP | E5: =_xlfn.XLOOKUP(C:C,'Price List'!C:C,'Price List'!K:K) -> 0 | F5: =_xlfn.XLOOKUP(C:C,'Price List'!C:C,'Price List'!E:E) -> 20 | G5: =_xlfn.XLOOKUP(C:C,'Price List'!C:C,'Price List'!F:F) -> 45 GR | H5: 2920 | I5: TOL Calgary | J5: 20250828 | K5: 1100 | L5: 46170 | M5: 5 | N5: =C5 & "_" & 2910 -> 10020850_2910 | O5: =_xlfn.XLOOKUP(N5,Allocation!H:H,Allocation!C:C,0) -> 0 | P5: =M5-O5 -> 5
A6: =_xlfn.XLOOKUP(C:C,'Price List'!C:C,'Price List'!A:A) -> JASON MULDOON PT | B6: CARL BUDDIG | C6: 10054147 | D6: CB CORNED BEEF | E6: =_xlfn.XLOOKUP(C:C,'Price List'!C:C,'Price List'!K:K) -> 0 | F6: =_xlfn.XLOOKUP(C:C,'Price List'!C:C,'Price List'!E:E) -> 12 | G6: =_xlfn.XLOOKUP(C:C,'Price List'!C:C,'Price List'!F:F) -> 55 GR | H6: 2920 | I6: TOL Calgary | J6: 26056 | K6: 1100 | L6: 46172 | M6: 7 | N6: =C6 & "_" & 2910 -> 10054147_2910 | O6: =_xlfn.XLOOKUP(N6,Allocation!H:H,Allocation!C:C,0) -> 0 | P6: =M6-O6 -> 7
A7: =_xlfn.XLOOKUP(C:C,'Price List'!C:C,'Price List'!A:A) -> SAMANTHA RODRIGUES GB | B7: MCVITIES | C7: 30083538 | D7: MCV DISP - DIGESTIVE ORIG | E7: =_xlfn.XLOOKUP(C:C,'Price List'!C:C,'Price List'!K:K) -> 0 | F7: =_xlfn.XLOOKUP(C:C,'Price List'!C:C,'Price List'!E:E) -> 48 | G7: =_xlfn.XLOOKUP(C:C,'Price List'!C:C,'Price List'!F:F) -> SHIPPER | H7: 2920 | I7: TOL Calgary | J7: 1000000033 | K7: 1100 | L7: 46172 | M7: 3 | N7: =C7 & "_" & 2910 -> 30083538_2910 | O7: =_xlfn.XLOOKUP(N7,Allocation!H:H,Allocation!C:C,0) -> 0 | P7: =M7-O7 -> 3
A8: =_xlfn.XLOOKUP(C:C,'Price List'!C:C,'Price List'!A:A) -> NANCY QUISPE PT | B8: THE SPICE TAILOR | C8: 10017604 | D8: TST PUNJAB CHICKPEA MASALA | E8: =_xlfn.XLOOKUP(C:C,'Price List'!C:C,'Price List'!K:K) -> 0 | F8: =_xlfn.XLOOKUP(C:C,'Price List'!C:C,'Price List'!E:E) -> 5 | G8: =_xlfn.XLOOKUP(C:C,'Price List'!C:C,'Price List'!F:F) -> 375 ML | H8: 2920 | I8: TOL Calgary | J8: 4183T | K8: 1100 | L8: 46173 | M8: 145 | N8: =C8 & "_" & 2910 -> 10017604_2910 | O8: =_xlfn.XLOOKUP(N8,Allocation!H:H,Allocation!C:C,0) -> 0 | P8: =M8-O8 -> 145
A9: =_xlfn.XLOOKUP(C:C,'Price List'!C:C,'Price List'!A:A) -> MICHELLE JEWELL NT | B9: SCHAR | C9: 10038127 | D9: SCHAR BREAD DELI SOURDOH GF | E9: =_xlfn.XLOOKUP(C:C,'Price List'!C:C,'Price List'!K:K) -> 0 | F9: =_xlfn.XLOOKUP(C:C,'Price List'!C:C,'Price List'!E:E) -> 5 | G9: =_xlfn.XLOOKUP(C:C,'Price List'!C:C,'Price List'!F:F) -> 240 GR | H9: 2920 | I9: TOL Calgary | J9: 260601D | K9: 1100 | L9: 46174 | M9: 119 | N9: =C9 & "_" & 2910 -> 10038127_2910 | O9: =_xlfn.XLOOKUP(N9,Allocation!H:H,Allocation!C:C,0) -> 0 | P9: =M9-O9 -> 119
A10: =_xlfn.XLOOKUP(C:C,'Price List'!C:C,'Price List'!A:A) -> NIKISHA MOHAMMED | B10: GREEN & BLACKS | C10: 10043078 | D10: G&B DARK CHOC GINGER ORG | E10: =_xlfn.XLOOKUP(C:C,'Price List'!C:C,'Price List'!K:K) -> 0 | F10: =_xlfn.XLOOKUP(C:C,'Price List'!C:C,'Price List'!E:E) -> 10 | G10: =_xlfn.XLOOKUP(C:C,'Price List'!C:C,'Price List'!F:F) -> 90 GR | H10: 2920 | I10: TOL Calgary | J10: OWR0344931 | K10: 1100 | L10: 46179 | M10: 2 | N10: =C10 & "_" & 2910 -> 10043078_2910 | O10: =_xlfn.XLOOKUP(N10,Allocation!H:H,Allocation!C:C,0) -> 0 | P10: =M10-O10 -> 2
A11: =_xlfn.XLOOKUP(C:C,'Price List'!C:C,'Price List'!A:A) -> NIKISHA MOHAMMED | B11: MY COOKING BOX | C11: 10041273 | D11: MCB PIZZA ITALIAN PIZZA CRST | E11: =_xlfn.XLOOKUP(C:C,'Price List'!C:C,'Price List'!K:K) -> 0 | F11: =_xlfn.XLOOKUP(C:C,'Price List'!C:C,'Price List'!E:E) -> 7 | G11: =_xlfn.XLOOKUP(C:C,'Price List'!C:C,'Price List'!F:F) -> 933 GR | H11: 2920 | I11: TOL Calgary | J11: LT250325CP | K11: 1100 | L11: 46179 | M11: 25 | N11: =C11 & "_" & 2910 -> 10041273_2910 | O11: =_xlfn.XLOOKUP(N11,Allocation!H:H,Allocation!C:C,0) -> 0 | P11: =M11-O11 -> 25
A12: =_xlfn.XLOOKUP(C:C,'Price List'!C:C,'Price List'!A:A) -> NIKISHA MOHAMMED | B12: MY COOKING BOX | C12: 10041273 | D12: MCB PIZZA ITALIAN PIZZA CRST | E12: =_xlfn.XLOOKUP(C:C,'Price List'!C:C,'Price List'!K:K) -> 0 | F12: =_xlfn.XLOOKUP(C:C,'Price List'!C:C,'Price List'!E:E) -> 7 | G12: =_xlfn.XLOOKUP(C:C,'Price List'!C:C,'Price List'!F:F) -> 933 GR | H12: 2920 | I12: TOL Calgary | J12: LT260325CP | K12: 1100 | L12: 46179 | M12: 45 | N12: =C12 & "_" & 2910 -> 10041273_2910 | O12: =_xlfn.XLOOKUP(N12,Allocation!H:H,Allocation!C:C,0) -> 0 | P12: =M12-O12 -> 45
A13: =_xlfn.XLOOKUP(C:C,'Price List'!C:C,'Price List'!A:A) -> ANABELA NEVES PR | B13: BEL BOURSIN | C13: 10061010 | D13: BEL BOUR 150G GARLIC & HERB | E13: =_xlfn.XLOOKUP(C:C,'Price List'!C:C,'Price List'!K:K) -> 0 | F13: =_xlfn.XLOOKUP(C:C,'Price List'!C:C,'Price List'!E:E) -> 12 | G13: =_xlfn.XLOOKUP(C:C,'Price List'!C:C,'Price List'!F:F) -> 150 GR | H13: 2920 | I13: TOL Calgary | J13: AG0431J | K13: 1100 | L13: 46180 | M13: 42 | N13: =C13 & "_" & 2910 -> 10061010_2910 | O13: =_xlfn.XLOOKUP(N13,Allocation!H:H,Allocation!C:C,0) -> 0 | P13: =M13-O13 -> 42
... A24: =_xlfn.XLOOKUP(C:C,'Price List'!C:C,'Price List'!A:A) -> AMOL PRAKASH | B24: KINNIKINNICK | C24: 10015808 | D24: KKF FZN DONUTS MAPLE GLAZED | E24: =_xlfn.XLOOKUP(C:C,'Price List'!C:C,'Price List'!K:K) -> 0 | F24: =_xlfn.XLOOKUP(C:C,'Price List'!C:C,'Price List'!E:E) -> 8 | G24: =_xlfn.XLOOKUP(C:C,'Price List'!C:C,'Price List'!F:F) -> 320 GR | H24: 2925 | I24: Lineage Calgary CS | J24: 2026JN15 | K24: 1100 | L24: 46188 | M24: 8 | N24: =C24 & "_" & 2910 -> 10015808_2910 | O24: =_xlfn.XLOOKUP(N24,Allocation!H:H,Allocation!C:C,0) -> 0 | P24: =M24-O24 -> 8
A25: =_xlfn.XLOOKUP(C:C,'Price List'!C:C,'Price List'!A:A) -> SERENA LEE PR | B25: AGROPUR | C25: 10019641 | D25: AGROSGN BRIE CHEVALR TC 650G | E25: KG | F25: =_xlfn.XLOOKUP(C:C,'Price List'!C:C,'Price List'!E:E) -> 4 | G25: =_xlfn.XLOOKUP(C:C,'Price List'!C:C,'Price List'!F:F) -> 650 GR | H25: 2920 | I25: TOL Calgary | J25: 20260616 | K25: 1100 | L25: 46189 | M25: 2 | N25: =C25 & "_" & 2910 -> 10019641_2910 | O25: =_xlfn.XLOOKUP(N25,Allocation!H:H,Allocation!C:C,0) -> 0 | P25: =M25-O25 -> 2
A26: =_xlfn.XLOOKUP(C:C,'Price List'!C:C,'Price List'!A:A) -> SERENA LEE PR | B26: AGROPUR | C26: 10019704 | D26: OKA CHEESE ORIGINAL 1X2.5KG | E26: KG | F26: =_xlfn.XLOOKUP(C:C,'Price List'!C:C,'Price List'!E:E) -> 1 | G26: =_xlfn.XLOOKUP(C:C,'Price List'!C:C,'Price List'!F:F) -> 2.5 KG | H26: 2920 | I26: TOL Calgary | J26: 20260616 | K26: 1100 | L26: 46189 | M26: 1 | N26: =C26 & "_" & 2910 -> 10019704_2910 | O26: =_xlfn.XLOOKUP(N26,Allocation!H:H,Allocation!C:C,0) -> 0 | P26: =M26-O26 -> 1
A27: =_xlfn.XLOOKUP(C:C,'Price List'!C:C,'Price List'!A:A) -> SERENA LEE PR | B27: AGROPUR | C27: 10019704 | D27: OKA CHEESE ORIGINAL 1X2.5KG | E27: KG | F27: =_xlfn.XLOOKUP(C:C,'Price List'!C:C,'Price List'!E:E) -> 1 | G27: =_xlfn.XLOOKUP(C:C,'Price List'!C:C,'Price List'!F:F) -> 2.5 KG | H27: 2920 | I27: TOL Calgary | J27: 20260617 | K27: 1100 | L27: 46190 | M27: 2 | N27: =C27 & "_" & 2910 -> 10019704_2910 | O27: =_xlfn.XLOOKUP(N27,Allocation!H:H,Allocation!C:C,0) -> 0 | P27: =M27-O27 -> 2
A28: =_xlfn.XLOOKUP(C:C,'Price List'!C:C,'Price List'!A:A) -> ANABELA NEVES PR | B28: STONETOWN ARTISAN CH | C28: 10052112 | D28: STW 170G FARMSTD EMMENTAL | E28: =_xlfn.XLOOKUP(C:C,'Price List'!C:C,'Price List'!K:K) -> 0 | F28: =_xlfn.XLOOKUP(C:C,'Price List'!C:C,'Price List'!E:E) -> 12 | G28: =_xlfn.XLOOKUP(C:C,'Price List'!C:C,'Price List'!F:F) -> 170 GR | H28: 2920 | I28: TOL Calgary | J28: 9.9.25/30. | K28: 1100 | L28: 46191 | M28: 3 | N28: =C28 & "_" & 2910 -> 10052112_2910 | O28: =_xlfn.XLOOKUP(N28,Allocation!H:H,Allocation!C:C,0) -> 0 | P28: =M28-O28 -> 3
A29: =_xlfn.XLOOKUP(C:C,'Price List'!C:C,'Price List'!A:A) -> TRACEY LAWRENCE | B29: KETTLE CHIPS | C29: 10066215 | D29: KC HONEY DIJON 56G GF | E29: =_xlfn.XLOOKUP(C:C,'Price List'!C:C,'Price List'!K:K) -> 0 | F29: =_xlfn.XLOOKUP(C:C,'Price List'!C:C,'Price List'!E:E) -> 24 | G29: =_xlfn.XLOOKUP(C:C,'Price List'!C:C,'Price List'!F:F) -> 56 GR | H29: 2920 | I29: TOL Calgary | J29: 20JUN2026 | K29: 1100 | L29: 46193 | M29: 7 | N29: =C29 & "_" & 2910 -> 10066215_2910 | O29: =_xlfn.XLOOKUP(N29,Allocation!H:H,Allocation!C:C,0) -> 0 | P29: =M29-O29 -> 7
A30: =_xlfn.XLOOKUP(C:C,'Price List'!C:C,'Price List'!A:A) -> NATASHA KING PR | B30: KROON | C30: 10030187 | D30: KROON GOUDA MEDIUM | E30: KG | F30: =_xlfn.XLOOKUP(C:C,'Price List'!C:C,'Price List'!E:E) -> 1 | G30: =_xlfn.XLOOKUP(C:C,'Price List'!C:C,'Price List'!F:F) -> 4.5 KG | H30: 2920 | I30: TOL Calgary | J30: 10G8BR1 | K30: 1100 | L30: 46193 | M30: 1 | N30: =C30 & "_" & 2910 -> 10030187_2910 | O30: =_xlfn.XLOOKUP(N30,Allocation!H:H,Allocation!C:C,0) -> 0 | P30: =M30-O30 -> 1
A31: =_xlfn.XLOOKUP(C:C,'Price List'!C:C,'Price List'!A:A) -> SERENA LEE PR | B31: AGROPUR | C31: 10019780 | D31: SNO BLACK BOMBER 1X2KG | E31: KG | F31: =_xlfn.XLOOKUP(C:C,'Price List'!C:C,'Price List'!E:E) -> 1 | G31: =_xlfn.XLOOKUP(C:C,'Price List'!C:C,'Price List'!F:F) -> 2 KG | H31: 2920 | I31: TOL Calgary | J31: 20260622 | K31: 1100 | L31: 46195 | M31: 28 | N31: =C31 & "_" & 2910 -> 10019780_2910 | O31: =_xlfn.XLOOKUP(N31,Allocation!H:H,Allocation!C:C,0) -> 0 | P31: =M31-O31 -> 28
A32: =_xlfn.XLOOKUP(C:C,'Price List'!C:C,'Price List'!A:A) -> ASIF AHMAD GB | B32: BLUE DIAMOND BEVERAG | C32: 10016405 | D32: BD ALM BREEZE UNSWT CHOCOLAT | E32: =_xlfn.XLOOKUP(C:C,'Price List'!C:C,'Price List'!K:K) -> 0 | F32: =_xlfn.XLOOKUP(C:C,'Price List'!C:C,'Price List'!E:E) -> 12 | G32: =_xlfn.XLOOKUP(C:C,'Price List'!C:C,'Price List'!F:F) -> 946 ML | H32: 2920 | I32: TOL Calgary | J32: 6AT25173A | K32: 1100 | L32: 46195 | M32: 72 | N32: =C32 & "_" & 2910 -> 10016405_2910 | O32: =_xlfn.XLOOKUP(N32,Allocation!H:H,Allocation!C:C,0) -> 0 | P32: =M32-O32 -> 72
A33: =_xlfn.XLOOKUP(C:C,'Price List'!C:C,'Price List'!A:A) -> ANABELA NEVES PR | B33: BOTHWELL CHEESE | C33: 10100089 | D33: BC RED HOT CHILI MJ | E33: =_xlfn.XLOOKUP(C:C,'Price List'!C:C,'Price List'!K:K) -> 0 | F33: =_xlfn.XLOOKUP(C:C,'Price List'!C:C,'Price List'!E:E) -> 12 | G33: =_xlfn.XLOOKUP(C:C,'Price List'!C:C,'Price List'!F:F) -> 540 GR | H33: 2920 | I33: TOL Calgary | J33: 20251027 | K33: 1100 | L33: 46197 | M33: 10 | N33: =C33 & "_" & 2910 -> 10100089_2910 | O33: =_xlfn.XLOOKUP(N33,Allocation!H:H,Allocation!C:C,0) -> 0 | P33: =M33-O33 -> 10
A34: =_xlfn.XLOOKUP(C:C,'Price List'!C:C,'Price List'!A:A) -> WARREN PARK | B34: LAID BACK SNACKS | C34: 10020851 | D34: LBS POSH PRALINE ALMD 45G | E34: =_xlfn.XLOOKUP(C:C,'Price List'!C:C,'Price List'!K:K) -> 0 | F34: =_xlfn.XLOOKUP(C:C,'Price List'!C:C,'Price List'!E:E) -> 20 | G34: =_xlfn.XLOOKUP(C:C,'Price List'!C:C,'Price List'!F:F) -> 45 GR | H34: 2920 | I34: TOL Calgary | J34: 20250924 | K34: 1100 | L34: 46197 | M34: 4 | N34: =C34 & "_" & 2910 -> 10020851_2910 | O34: =_xlfn.XLOOKUP(N34,Allocation!H:H,Allocation!C:C,0) -> 0 | P34: =M34-O34 -> 4
A35: =_xlfn.XLOOKUP(C:C,'Price List'!C:C,'Price List'!A:A) -> ANABELA NEVES PR | B35: ALIMENTIAS SPAIN CHE | C35: 10013759 | D35: BULK SHP CHS AGD IN CASKS | E35: KG | F35: =_xlfn.XLOOKUP(C:C,'Price List'!C:C,'Price List'!E:E) -> 2 | G35: =_xlfn.XLOOKUP(C:C,'Price List'!C:C,'Price List'!F:F) -> 3 KG | H35: 2920 | I35: TOL Calgary | J35: 17625 | K35: 1100 | L35: 46198 | M35: 2 | N35: =C35 & "_" & 2910 -> 10013759_2910 | O35: =_xlfn.XLOOKUP(N35,Allocation!H:H,Allocation!C:C,0) -> 0 | P35: =M35-O35 -> 2
A36: =_xlfn.XLOOKUP(C:C,'Price List'!C:C,'Price List'!A:A) -> NATASHA KING PR | B36: TRADITIONAL CHEESE | C36: 10097047 | D36: TRD IRISH CHED BK PEP CHIVE | E36: =_xlfn.XLOOKUP(C:C,'Price List'!C:C,'Price List'!K:K) -> 0 | F36: =_xlfn.XLOOKUP(C:C,'Price List'!C:C,'Price List'!E:E) -> 8 | G36: =_xlfn.XLOOKUP(C:C,'Price List'!C:C,'Price List'!F:F) -> 150 GR | H36: 2920 | I36: TOL Calgary | J36: LOT-110761 | K36: 1100 | L36: 46198 | M36: 3 | N36: =C36 & "_" & 2910 -> 10097047_2910 | O36: =_xlfn.XLOOKUP(N36,Allocation!H:H,Allocation!C:C,0) -> 0 | P36: =M36-O36 -> 3
A37: =_xlfn.XLOOKUP(C:C,'Price List'!C:C,'Price List'!A:A) -> SAMANTHA RODRIGUES GB | B37: KIKKOMAN RETAIL | C37: 10059163 | D37: KKM SOY SHIPPER 36CT | E37: =_xlfn.XLOOKUP(C:C,'Price List'!C:C,'Price List'!K:K) -> 0 | F37: =_xlfn.XLOOKUP(C:C,'Price List'!C:C,'Price List'!E:E) -> 1 | G37: =_xlfn.XLOOKUP(C:C,'Price List'!C:C,'Price List'!F:F) -> 296 ML | H37: 2920 | I37: TOL Calgary | J37: 177BC | K37: 1100 | L37: 46199 | M37: 42 | N37: =C37 & "_" & 2910 -> 10059163_2910 | O37: =_xlfn.XLOOKUP(N37,Allocation!H:H,Allocation!C:C,0) -> 0 | P37: =M37-O37 -> 42
A38: =_xlfn.XLOOKUP(C:C,'Price List'!C:C,'Price List'!A:A) -> TRACEY LAWRENCE | B38: KETTLE CHIPS | C38: 10066217 | D38: KC SEA SALT 56G GF | E38: =_xlfn.XLOOKUP(C:C,'Price List'!C:C,'Price List'!K:K) -> 0 | F38: =_xlfn.XLOOKUP(C:C,'Price List'!C:C,'Price List'!E:E) -> 24 | G38: =_xlfn.XLOOKUP(C:C,'Price List'!C:C,'Price List'!F:F) -> 56 GR | H38: 2920 | I38: TOL Calgary | J38: 27JUN2026 | K38: 1100 | L38: 46200 | M38: 5 | N38: =C38 & "_" & 2910 -> 10066217_2910 | O38: =_xlfn.XLOOKUP(N38,Allocation!H:H,Allocation!C:C,0) -> 0 | P38: =M38-O38 -> 5
A39: =_xlfn.XLOOKUP(C:C,'Price List'!C:C,'Price List'!A:A) -> MICHELLE JEWELL NT | B39: SCHAR | C39: 10038132 | D39: SCHAR BREAD A B 10GRN 8PK GF | E39: =_xlfn.XLOOKUP(C:C,'Price List'!C:C,'Price List'!K:K) -> 0 | F39: =_xlfn.XLOOKUP(C:C,'Price List'!C:C,'Price List'!E:E) -> 8 | G39: =_xlfn.XLOOKUP(C:C,'Price List'!C:C,'Price List'!F:F) -> 400 GR | H39: 2920 | I39: TOL Calgary | J39: 06272026A | K39: 1100 | L39: 46200 | M39: 162 | N39: =C39 & "_" & 2910 -> 10038132_2910 | O39: =_xlfn.XLOOKUP(N39,Allocation!H:H,Allocation!C:C,0) -> 0 | P39: =M39-O39 -> 162
A40: =_xlfn.XLOOKUP(C:C,'Price List'!C:C,'Price List'!A:A) -> SERENA LEE PR | B40: AGROPUR | C40: 10100360 | D40: CASHEL BLUE 2X1.5KG | E40: KG | F40: =_xlfn.XLOOKUP(C:C,'Price List'!C:C,'Price List'!E:E) -> 2 | G40: =_xlfn.XLOOKUP(C:C,'Price List'!C:C,'Price List'!F:F) -> 1.5 KG | H40: 2920 | I40: TOL Calgary | J40: 25510502 | K40: 1100 | L40: 46201 | M40: 3 | N40: =C40 & "_" & 2910 -> 10100360_2910 | O40: =_xlfn.XLOOKUP(N40,Allocation!H:H,Allocation!C:C,0) -> 0 | P40: =M40-O40 -> 3
A41: =_xlfn.XLOOKUP(C:C,'Price List'!C:C,'Price List'!A:A) -> NANCY QUISPE PT | B41: SHARWOODS | C41: 10050282 | D41: SHARWOODS BUTTERCHICK LITE | E41: =_xlfn.XLOOKUP(C:C,'Price List'!C:C,'Price List'!K:K) -> 0 | F41: =_xlfn.XLOOKUP(C:C,'Price List'!C:C,'Price List'!E:E) -> 6 | G41: =_xlfn.XLOOKUP(C:C,'Price List'!C:C,'Price List'!F:F) -> 395 ML | H41: 2920 | I41: TOL Calgary | J41: 103965 | K41: 1100 | L41: 46201 | M41: 1 | N41: =C41 & "_" & 2910 -> 10050282_2910 | O41: =_xlfn.XLOOKUP(N41,Allocation!H:H,Allocation!C:C,0) -> 0 | P41: =M41-O41 -> 1
A42: =_xlfn.XLOOKUP(C:C,'Price List'!C:C,'Price List'!A:A) -> Michael Gambino PR | B42: PARMELA CREAMERY | C42: 10045482 | D42: PC SHREDDED MOZZARELLA STYLE | E42: =_xlfn.XLOOKUP(C:C,'Price List'!C:C,'Price List'!K:K) -> 0 | F42: =_xlfn.XLOOKUP(C:C,'Price List'!C:C,'Price List'!E:E) -> 8 | G42: =_xlfn.XLOOKUP(C:C,'Price List'!C:C,'Price List'!F:F) -> 198 GR | H42: 2920 | I42: TOL Calgary | J42: 0062603117 | K42: 1100 | L42: 46202 | M42: 16 | N42: =C42 & "_" & 2910 -> 10045482_2910 | O42: =_xlfn.XLOOKUP(N42,Allocation!H:H,Allocation!C:C,0) -> 0 | P42: =M42-O42 -> 16
A43: =_xlfn.XLOOKUP(C:C,'Price List'!C:C,'Price List'!A:A) -> ANABELA NEVES PR | B43: DEVON CREAM COMPANY | C43: 10018980 | D43: DC CLOTTED CREAM 12X170G | E43: =_xlfn.XLOOKUP(C:C,'Price List'!C:C,'Price List'!K:K) -> 0 | F43: =_xlfn.XLOOKUP(C:C,'Price List'!C:C,'Price List'!E:E) -> 12 | G43: =_xlfn.XLOOKUP(C:C,'Price List'!C:C,'Price List'!F:F) -> 170 GR | H43: 2920 | I43: TOL Calgary | J43: 50186 | K43: 1100 | L43: 46203 | M43: 250 | N43: =C43 & "_" & 2910 -> 10018980_2910 | O43: =_xlfn.XLOOKUP(N43,Allocation!H:H,Allocation!C:C,0) -> 0 | P43: =M43-O43 -> 250
A44: =_xlfn.XLOOKUP(C:C,'Price List'!C:C,'Price List'!A:A) -> ANABELA NEVES PR | B44: DEVON CREAM COMPANY | C44: 10018980 | D44: DC CLOTTED CREAM 12X170G | E44: =_xlfn.XLOOKUP(C:C,'Price List'!C:C,'Price List'!K:K) -> 0 | F44: =_xlfn.XLOOKUP(C:C,'Price List'!C:C,'Price List'!E:E) -> 12 | G44: =_xlfn.XLOOKUP(C:C,'Price List'!C:C,'Price List'!F:F) -> 170 GR | H44: 2920 | I44: TOL Calgary | J44: 50187 | K44: 1100 | L44: 46203 | M44: 260 | N44: =C44 & "_" & 2910 -> 10018980_2910 | O44: =_xlfn.XLOOKUP(N44,Allocation!H:H,Allocation!C:C,0) -> 0 | P44: =M44-O44 -> 260
A45: =_xlfn.XLOOKUP(C:C,'Price List'!C:C,'Price List'!A:A) -> ANABELA NEVES PR | B45: DEVON CREAM COMPANY | C45: 10018980 | D45: DC CLOTTED CREAM 12X170G | E45: =_xlfn.XLOOKUP(C:C,'Price List'!C:C,'Price List'!K:K) -> 0 | F45: =_xlfn.XLOOKUP(C:C,'Price List'!C:C,'Price List'!E:E) -> 12 | G45: =_xlfn.XLOOKUP(C:C,'Price List'!C:C,'Price List'!F:F) -> 170 GR | H45: 2920 | I45: TOL Calgary | J45: 50508 | K45: 1100 | L45: 46203 | M45: 208 | N45: =C45 & "_" & 2910 -> 10018980_2910 | O45: =_xlfn.XLOOKUP(N45,Allocation!H:H,Allocation!C:C,0) -> 0 | P45: =M45-O45 -> 208
A46: =_xlfn.XLOOKUP(C:C,'Price List'!C:C,'Price List'!A:A) -> ANABELA NEVES PR | B46: DEVON CREAM COMPANY | C46: 10019099 | D46: DC DOUBLE DEVON CREAM 12X170G | E46: =_xlfn.XLOOKUP(C:C,'Price List'!C:C,'Price List'!K:K) -> 0 | F46: =_xlfn.XLOOKUP(C:C,'Price List'!C:C,'Price List'!E:E) -> 12 | G46: =_xlfn.XLOOKUP(C:C,'Price List'!C:C,'Price List'!F:F) -> 170 GR | H46: 2920 | I46: TOL Calgary | J46: 44425 | K46: 1100 | L46: 46203 | M46: 44 | N46: =C46 & "_" & 2910 -> 10019099_2910 | O46: =_xlfn.XLOOKUP(N46,Allocation!H:H,Allocation!C:C,0) -> 0 | P46: =M46-O46 -> 44
A47: =_xlfn.XLOOKUP(C:C,'Price List'!C:C,'Price List'!A:A) -> ANABELA NEVES PR | B47: DEVON CREAM COMPANY | C47: 10019099 | D47: DC DOUBLE DEVON CREAM 12X170G | E47: =_xlfn.XLOOKUP(C:C,'Price List'!C:C,'Price List'!K:K) -> 0 | F47: =_xlfn.XLOOKUP(C:C,'Price List'!C:C,'Price List'!E:E) -> 12 | G47: =_xlfn.XLOOKUP(C:C,'Price List'!C:C,'Price List'!F:F) -> 170 GR | H47: 2920 | I47: TOL Calgary | J47: 45908 | K47: 1100 | L47: 46203 | M47: 101 | N47: =C47 & "_" & 2910 -> 10019099_2910 | O47: =_xlfn.XLOOKUP(N47,Allocation!H:H,Allocation!C:C,0) -> 0 | P47: =M47-O47 -> 101
A48: =_xlfn.XLOOKUP(C:C,'Price List'!C:C,'Price List'!A:A) -> ANABELA NEVES PR | B48: DEVON CREAM COMPANY | C48: 10019099 | D48: DC DOUBLE DEVON CREAM 12X170G | E48: =_xlfn.XLOOKUP(C:C,'Price List'!C:C,'Price List'!K:K) -> 0 | F48: =_xlfn.XLOOKUP(C:C,'Price List'!C:C,'Price List'!E:E) -> 12 | G48: =_xlfn.XLOOKUP(C:C,'Price List'!C:C,'Price List'!F:F) -> 170 GR | H48: 2920 | I48: TOL Calgary | J48: 46147 | K48: 1100 | L48: 46203 | M48: 39 | N48: =C48 & "_" & 2910 -> 10019099_2910 | O48: =_xlfn.XLOOKUP(N48,Allocation!H:H,Allocation!C:C,0) -> 0 | P48: =M48-O48 -> 39
A49: =_xlfn.XLOOKUP(C:C,'Price List'!C:C,'Price List'!A:A) -> ANABELA NEVES PR | B49: DEVON CREAM COMPANY | C49: 10019099 | D49: DC DOUBLE DEVON CREAM 12X170G | E49: =_xlfn.XLOOKUP(C:C,'Price List'!C:C,'Price List'!K:K) -> 0 | F49: =_xlfn.XLOOKUP(C:C,'Price List'!C:C,'Price List'!E:E) -> 12 | G49: =_xlfn.XLOOKUP(C:C,'Price List'!C:C,'Price List'!F:F) -> 170 GR | H49: 2920 | I49: TOL Calgary | J49: 46623 | K49: 1100 | L49: 46203 | M49: 1 | N49: =C49 & "_" & 2910 -> 10019099_2910 | O49: =_xlfn.XLOOKUP(N49,Allocation!H:H,Allocation!C:C,0) -> 0 | P49: =M49-O49 -> 1
A50: =_xlfn.XLOOKUP(C:C,'Price List'!C:C,'Price List'!A:A) -> ANABELA NEVES PR | B50: DEVON CREAM COMPANY | C50: 10019099 | D50: DC DOUBLE DEVON CREAM 12X170G | E50: =_xlfn.XLOOKUP(C:C,'Price List'!C:C,'Price List'!K:K) -> 0 | F50: =_xlfn.XLOOKUP(C:C,'Price List'!C:C,'Price List'!E:E) -> 12 | G50: =_xlfn.XLOOKUP(C:C,'Price List'!C:C,'Price List'!F:F) -> 170 GR | H50: 2920 | I50: TOL Calgary | J50: 47397 | K50: 1100 | L50: 46203 | M50: 305 | N50: =C50 & "_" & 2910 -> 10019099_2910 | O50: =_xlfn.XLOOKUP(N50,Allocation!H:H,Allocation!C:C,0) -> 0 | P50: =M50-O50 -> 305
...
